[2022-12-03 02:39:29,714] {taskinstance.py:1032} INFO - Dependencies all met for <TaskInstance: data_ingestion_gcs_dag.save_as_csv manual__2022-12-03T02:39:24.814374+00:00 [queued]>
[2022-12-03 02:39:29,727] {taskinstance.py:1032} INFO - Dependencies all met for <TaskInstance: data_ingestion_gcs_dag.save_as_csv manual__2022-12-03T02:39:24.814374+00:00 [queued]>
[2022-12-03 02:39:29,727] {taskinstance.py:1238} INFO - 
--------------------------------------------------------------------------------
[2022-12-03 02:39:29,727] {taskinstance.py:1239} INFO - Starting attempt 1 of 2
[2022-12-03 02:39:29,727] {taskinstance.py:1240} INFO - 
--------------------------------------------------------------------------------
[2022-12-03 02:39:29,752] {taskinstance.py:1259} INFO - Executing <Task(PythonOperator): save_as_csv> on 2022-12-03 02:39:24.814374+00:00
[2022-12-03 02:39:29,763] {standard_task_runner.py:52} INFO - Started process 179 to run task
[2022-12-03 02:39:29,770] {standard_task_runner.py:76} INFO - Running: ['***', 'tasks', 'run', 'data_ingestion_gcs_dag', 'save_as_csv', 'manual__2022-12-03T02:39:24.814374+00:00', '--job-id', '47', '--raw', '--subdir', 'DAGS_FOLDER/data_ingestion_gcs_dag.py', '--cfg-path', '/tmp/tmpr3e5go3t', '--error-file', '/tmp/tmputmzyc3a']
[2022-12-03 02:39:29,772] {standard_task_runner.py:77} INFO - Job 47: Subtask save_as_csv
[2022-12-03 02:39:29,875] {logging_mixin.py:109} INFO - Running <TaskInstance: data_ingestion_gcs_dag.save_as_csv manual__2022-12-03T02:39:24.814374+00:00 [running]> on host c87e816ea86f
[2022-12-03 02:39:29,957] {taskinstance.py:1426} INFO - Exporting the following env vars:
AIRFLOW_CTX_DAG_OWNER=***
AIRFLOW_CTX_DAG_ID=data_ingestion_gcs_dag
AIRFLOW_CTX_TASK_ID=save_as_csv
AIRFLOW_CTX_EXECUTION_DATE=2022-12-03T02:39:24.814374+00:00
AIRFLOW_CTX_DAG_RUN_ID=manual__2022-12-03T02:39:24.814374+00:00
[2022-12-03 02:39:29,973] {taskinstance.py:1700} ERROR - Task failed with exception
Traceback (most recent call last):
  File "/home/airflow/.local/lib/python3.7/site-packages/airflow/models/taskinstance.py", line 1329, in _run_raw_task
    self._execute_task_with_callbacks(context)
  File "/home/airflow/.local/lib/python3.7/site-packages/airflow/models/taskinstance.py", line 1455, in _execute_task_with_callbacks
    result = self._execute_task(context, self.task)
  File "/home/airflow/.local/lib/python3.7/site-packages/airflow/models/taskinstance.py", line 1511, in _execute_task
    result = execute_callable(context=context)
  File "/home/airflow/.local/lib/python3.7/site-packages/airflow/operators/python.py", line 174, in execute
    return_value = self.execute_callable()
  File "/home/airflow/.local/lib/python3.7/site-packages/airflow/operators/python.py", line 185, in execute_callable
    return self.python_callable(*self.op_args, **self.op_kwargs)
  File "/opt/airflow/dags/data_ingestion_gcs_dag.py", line 44, in save_as_csv
    table_arr = df['data'].to_numpy()
UnboundLocalError: local variable 'df' referenced before assignment
[2022-12-03 02:39:29,989] {taskinstance.py:1277} INFO - Marking task as UP_FOR_RETRY. dag_id=data_ingestion_gcs_dag, task_id=save_as_csv, execution_date=20221203T023924, start_date=20221203T023929, end_date=20221203T023929
[2022-12-03 02:39:30,006] {standard_task_runner.py:92} ERROR - Failed to execute job 47 for task save_as_csv
Traceback (most recent call last):
  File "/home/airflow/.local/lib/python3.7/site-packages/airflow/task/task_runner/standard_task_runner.py", line 85, in _start_by_fork
    args.func(args, dag=self.dag)
  File "/home/airflow/.local/lib/python3.7/site-packages/airflow/cli/cli_parser.py", line 48, in command
    return func(*args, **kwargs)
  File "/home/airflow/.local/lib/python3.7/site-packages/airflow/utils/cli.py", line 92, in wrapper
    return f(*args, **kwargs)
  File "/home/airflow/.local/lib/python3.7/site-packages/airflow/cli/commands/task_command.py", line 298, in task_run
    _run_task_by_selected_method(args, dag, ti)
  File "/home/airflow/.local/lib/python3.7/site-packages/airflow/cli/commands/task_command.py", line 107, in _run_task_by_selected_method
    _run_raw_task(args, ti)
  File "/home/airflow/.local/lib/python3.7/site-packages/airflow/cli/commands/task_command.py", line 184, in _run_raw_task
    error_file=args.error_file,
  File "/home/airflow/.local/lib/python3.7/site-packages/airflow/utils/session.py", line 70, in wrapper
    return func(*args, session=session, **kwargs)
  File "/home/airflow/.local/lib/python3.7/site-packages/airflow/models/taskinstance.py", line 1329, in _run_raw_task
    self._execute_task_with_callbacks(context)
  File "/home/airflow/.local/lib/python3.7/site-packages/airflow/models/taskinstance.py", line 1455, in _execute_task_with_callbacks
    result = self._execute_task(context, self.task)
  File "/home/airflow/.local/lib/python3.7/site-packages/airflow/models/taskinstance.py", line 1511, in _execute_task
    result = execute_callable(context=context)
  File "/home/airflow/.local/lib/python3.7/site-packages/airflow/operators/python.py", line 174, in execute
    return_value = self.execute_callable()
  File "/home/airflow/.local/lib/python3.7/site-packages/airflow/operators/python.py", line 185, in execute_callable
    return self.python_callable(*self.op_args, **self.op_kwargs)
  File "/opt/airflow/dags/data_ingestion_gcs_dag.py", line 44, in save_as_csv
    table_arr = df['data'].to_numpy()
UnboundLocalError: local variable 'df' referenced before assignment
[2022-12-03 02:39:30,037] {local_task_job.py:154} INFO - Task exited with return code 1
[2022-12-03 02:39:30,091] {local_task_job.py:264} INFO - 0 downstream tasks scheduled from follow-on schedule check
