[2022-12-03 02:09:29,456] {taskinstance.py:1032} INFO - Dependencies all met for <TaskInstance: data_ingestion_gcs_dag.call_dataset_task manual__2022-12-03T02:09:26.185053+00:00 [queued]>
[2022-12-03 02:09:29,476] {taskinstance.py:1032} INFO - Dependencies all met for <TaskInstance: data_ingestion_gcs_dag.call_dataset_task manual__2022-12-03T02:09:26.185053+00:00 [queued]>
[2022-12-03 02:09:29,477] {taskinstance.py:1238} INFO - 
--------------------------------------------------------------------------------
[2022-12-03 02:09:29,477] {taskinstance.py:1239} INFO - Starting attempt 1 of 2
[2022-12-03 02:09:29,477] {taskinstance.py:1240} INFO - 
--------------------------------------------------------------------------------
[2022-12-03 02:09:29,500] {taskinstance.py:1259} INFO - Executing <Task(PythonOperator): call_dataset_task> on 2022-12-03 02:09:26.185053+00:00
[2022-12-03 02:09:29,509] {standard_task_runner.py:52} INFO - Started process 186 to run task
[2022-12-03 02:09:29,521] {standard_task_runner.py:76} INFO - Running: ['***', 'tasks', 'run', 'data_ingestion_gcs_dag', 'call_dataset_task', 'manual__2022-12-03T02:09:26.185053+00:00', '--job-id', '41', '--raw', '--subdir', 'DAGS_FOLDER/data_ingestion_gcs_dag.py', '--cfg-path', '/tmp/tmpe1t2bdgb', '--error-file', '/tmp/tmp1br6iqhu']
[2022-12-03 02:09:29,523] {standard_task_runner.py:77} INFO - Job 41: Subtask call_dataset_task
[2022-12-03 02:09:29,754] {logging_mixin.py:109} INFO - Running <TaskInstance: data_ingestion_gcs_dag.call_dataset_task manual__2022-12-03T02:09:26.185053+00:00 [running]> on host c87e816ea86f
[2022-12-03 02:09:29,951] {taskinstance.py:1426} INFO - Exporting the following env vars:
AIRFLOW_CTX_DAG_OWNER=***
AIRFLOW_CTX_DAG_ID=data_ingestion_gcs_dag
AIRFLOW_CTX_TASK_ID=call_dataset_task
AIRFLOW_CTX_EXECUTION_DATE=2022-12-03T02:09:26.185053+00:00
AIRFLOW_CTX_DAG_RUN_ID=manual__2022-12-03T02:09:26.185053+00:00
[2022-12-03 02:09:30,108] {taskinstance.py:1700} ERROR - Task failed with exception
Traceback (most recent call last):
  File "/home/airflow/.local/lib/python3.7/site-packages/airflow/models/taskinstance.py", line 1329, in _run_raw_task
    self._execute_task_with_callbacks(context)
  File "/home/airflow/.local/lib/python3.7/site-packages/airflow/models/taskinstance.py", line 1455, in _execute_task_with_callbacks
    result = self._execute_task(context, self.task)
  File "/home/airflow/.local/lib/python3.7/site-packages/airflow/models/taskinstance.py", line 1511, in _execute_task
    result = execute_callable(context=context)
  File "/home/airflow/.local/lib/python3.7/site-packages/airflow/operators/python.py", line 174, in execute
    return_value = self.execute_callable()
  File "/home/airflow/.local/lib/python3.7/site-packages/airflow/operators/python.py", line 185, in execute_callable
    return self.python_callable(*self.op_args, **self.op_kwargs)
  File "/opt/airflow/dags/data_ingestion_gcs_dag.py", line 31, in fetch_api_task
    data = response['data'].json()
TypeError: 'Response' object is not subscriptable
[2022-12-03 02:09:30,166] {taskinstance.py:1277} INFO - Marking task as UP_FOR_RETRY. dag_id=data_ingestion_gcs_dag, task_id=call_dataset_task, execution_date=20221203T020926, start_date=20221203T020929, end_date=20221203T020930
[2022-12-03 02:09:30,222] {standard_task_runner.py:92} ERROR - Failed to execute job 41 for task call_dataset_task
Traceback (most recent call last):
  File "/home/airflow/.local/lib/python3.7/site-packages/airflow/task/task_runner/standard_task_runner.py", line 85, in _start_by_fork
    args.func(args, dag=self.dag)
  File "/home/airflow/.local/lib/python3.7/site-packages/airflow/cli/cli_parser.py", line 48, in command
    return func(*args, **kwargs)
  File "/home/airflow/.local/lib/python3.7/site-packages/airflow/utils/cli.py", line 92, in wrapper
    return f(*args, **kwargs)
  File "/home/airflow/.local/lib/python3.7/site-packages/airflow/cli/commands/task_command.py", line 298, in task_run
    _run_task_by_selected_method(args, dag, ti)
  File "/home/airflow/.local/lib/python3.7/site-packages/airflow/cli/commands/task_command.py", line 107, in _run_task_by_selected_method
    _run_raw_task(args, ti)
  File "/home/airflow/.local/lib/python3.7/site-packages/airflow/cli/commands/task_command.py", line 184, in _run_raw_task
    error_file=args.error_file,
  File "/home/airflow/.local/lib/python3.7/site-packages/airflow/utils/session.py", line 70, in wrapper
    return func(*args, session=session, **kwargs)
  File "/home/airflow/.local/lib/python3.7/site-packages/airflow/models/taskinstance.py", line 1329, in _run_raw_task
    self._execute_task_with_callbacks(context)
  File "/home/airflow/.local/lib/python3.7/site-packages/airflow/models/taskinstance.py", line 1455, in _execute_task_with_callbacks
    result = self._execute_task(context, self.task)
  File "/home/airflow/.local/lib/python3.7/site-packages/airflow/models/taskinstance.py", line 1511, in _execute_task
    result = execute_callable(context=context)
  File "/home/airflow/.local/lib/python3.7/site-packages/airflow/operators/python.py", line 174, in execute
    return_value = self.execute_callable()
  File "/home/airflow/.local/lib/python3.7/site-packages/airflow/operators/python.py", line 185, in execute_callable
    return self.python_callable(*self.op_args, **self.op_kwargs)
  File "/opt/airflow/dags/data_ingestion_gcs_dag.py", line 31, in fetch_api_task
    data = response['data'].json()
TypeError: 'Response' object is not subscriptable
[2022-12-03 02:09:30,286] {local_task_job.py:154} INFO - Task exited with return code 1
[2022-12-03 02:09:30,490] {local_task_job.py:264} INFO - 0 downstream tasks scheduled from follow-on schedule check
