[2022-12-03 01:33:05,915] {taskinstance.py:1032} INFO - Dependencies all met for <TaskInstance: data_ingestion_gcs_dag.save_as_csv scheduled__2022-12-02T00:00:00+00:00 [queued]>
[2022-12-03 01:33:05,929] {taskinstance.py:1032} INFO - Dependencies all met for <TaskInstance: data_ingestion_gcs_dag.save_as_csv scheduled__2022-12-02T00:00:00+00:00 [queued]>
[2022-12-03 01:33:05,930] {taskinstance.py:1238} INFO - 
--------------------------------------------------------------------------------
[2022-12-03 01:33:05,930] {taskinstance.py:1239} INFO - Starting attempt 1 of 2
[2022-12-03 01:33:05,930] {taskinstance.py:1240} INFO - 
--------------------------------------------------------------------------------
[2022-12-03 01:33:05,947] {taskinstance.py:1259} INFO - Executing <Task(PythonOperator): save_as_csv> on 2022-12-02 00:00:00+00:00
[2022-12-03 01:33:05,955] {standard_task_runner.py:52} INFO - Started process 124 to run task
[2022-12-03 01:33:05,961] {standard_task_runner.py:76} INFO - Running: ['***', 'tasks', 'run', 'data_ingestion_gcs_dag', 'save_as_csv', 'scheduled__2022-12-02T00:00:00+00:00', '--job-id', '29', '--raw', '--subdir', 'DAGS_FOLDER/data_ingestion_gcs_dag.py', '--cfg-path', '/tmp/tmpvjzj1vrq', '--error-file', '/tmp/tmpd0k9oaoq']
[2022-12-03 01:33:05,963] {standard_task_runner.py:77} INFO - Job 29: Subtask save_as_csv
[2022-12-03 01:33:06,046] {logging_mixin.py:109} INFO - Running <TaskInstance: data_ingestion_gcs_dag.save_as_csv scheduled__2022-12-02T00:00:00+00:00 [running]> on host c87e816ea86f
[2022-12-03 01:33:06,127] {taskinstance.py:1426} INFO - Exporting the following env vars:
AIRFLOW_CTX_DAG_OWNER=***
AIRFLOW_CTX_DAG_ID=data_ingestion_gcs_dag
AIRFLOW_CTX_TASK_ID=save_as_csv
AIRFLOW_CTX_EXECUTION_DATE=2022-12-02T00:00:00+00:00
AIRFLOW_CTX_DAG_RUN_ID=scheduled__2022-12-02T00:00:00+00:00
[2022-12-03 01:33:06,129] {taskinstance.py:1700} ERROR - Task failed with exception
Traceback (most recent call last):
  File "/home/airflow/.local/lib/python3.7/site-packages/airflow/models/taskinstance.py", line 1329, in _run_raw_task
    self._execute_task_with_callbacks(context)
  File "/home/airflow/.local/lib/python3.7/site-packages/airflow/models/taskinstance.py", line 1455, in _execute_task_with_callbacks
    result = self._execute_task(context, self.task)
  File "/home/airflow/.local/lib/python3.7/site-packages/airflow/models/taskinstance.py", line 1511, in _execute_task
    result = execute_callable(context=context)
  File "/home/airflow/.local/lib/python3.7/site-packages/airflow/operators/python.py", line 174, in execute
    return_value = self.execute_callable()
  File "/home/airflow/.local/lib/python3.7/site-packages/airflow/operators/python.py", line 185, in execute_callable
    return self.python_callable(*self.op_args, **self.op_kwargs)
  File "/opt/airflow/dags/data_ingestion_gcs_dag.py", line 33, in save_as_csv
    df = pd.read_json(src_file['data'])
TypeError: string indices must be integers
[2022-12-03 01:33:06,152] {taskinstance.py:1277} INFO - Marking task as UP_FOR_RETRY. dag_id=data_ingestion_gcs_dag, task_id=save_as_csv, execution_date=20221202T000000, start_date=20221203T013305, end_date=20221203T013306
[2022-12-03 01:33:06,176] {standard_task_runner.py:92} ERROR - Failed to execute job 29 for task save_as_csv
Traceback (most recent call last):
  File "/home/airflow/.local/lib/python3.7/site-packages/airflow/task/task_runner/standard_task_runner.py", line 85, in _start_by_fork
    args.func(args, dag=self.dag)
  File "/home/airflow/.local/lib/python3.7/site-packages/airflow/cli/cli_parser.py", line 48, in command
    return func(*args, **kwargs)
  File "/home/airflow/.local/lib/python3.7/site-packages/airflow/utils/cli.py", line 92, in wrapper
    return f(*args, **kwargs)
  File "/home/airflow/.local/lib/python3.7/site-packages/airflow/cli/commands/task_command.py", line 298, in task_run
    _run_task_by_selected_method(args, dag, ti)
  File "/home/airflow/.local/lib/python3.7/site-packages/airflow/cli/commands/task_command.py", line 107, in _run_task_by_selected_method
    _run_raw_task(args, ti)
  File "/home/airflow/.local/lib/python3.7/site-packages/airflow/cli/commands/task_command.py", line 184, in _run_raw_task
    error_file=args.error_file,
  File "/home/airflow/.local/lib/python3.7/site-packages/airflow/utils/session.py", line 70, in wrapper
    return func(*args, session=session, **kwargs)
  File "/home/airflow/.local/lib/python3.7/site-packages/airflow/models/taskinstance.py", line 1329, in _run_raw_task
    self._execute_task_with_callbacks(context)
  File "/home/airflow/.local/lib/python3.7/site-packages/airflow/models/taskinstance.py", line 1455, in _execute_task_with_callbacks
    result = self._execute_task(context, self.task)
  File "/home/airflow/.local/lib/python3.7/site-packages/airflow/models/taskinstance.py", line 1511, in _execute_task
    result = execute_callable(context=context)
  File "/home/airflow/.local/lib/python3.7/site-packages/airflow/operators/python.py", line 174, in execute
    return_value = self.execute_callable()
  File "/home/airflow/.local/lib/python3.7/site-packages/airflow/operators/python.py", line 185, in execute_callable
    return self.python_callable(*self.op_args, **self.op_kwargs)
  File "/opt/airflow/dags/data_ingestion_gcs_dag.py", line 33, in save_as_csv
    df = pd.read_json(src_file['data'])
TypeError: string indices must be integers
[2022-12-03 01:33:06,214] {local_task_job.py:154} INFO - Task exited with return code 1
[2022-12-03 01:33:06,273] {local_task_job.py:264} INFO - 0 downstream tasks scheduled from follow-on schedule check
