[2022-12-01 14:50:28,409] {taskinstance.py:1032} INFO - Dependencies all met for <TaskInstance: data_ingestion_gcs_dag.bigquery_external_table_task scheduled__2022-11-30T00:00:00+00:00 [queued]>
[2022-12-01 14:50:28,429] {taskinstance.py:1032} INFO - Dependencies all met for <TaskInstance: data_ingestion_gcs_dag.bigquery_external_table_task scheduled__2022-11-30T00:00:00+00:00 [queued]>
[2022-12-01 14:50:28,429] {taskinstance.py:1238} INFO - 
--------------------------------------------------------------------------------
[2022-12-01 14:50:28,430] {taskinstance.py:1239} INFO - Starting attempt 1 of 2
[2022-12-01 14:50:28,430] {taskinstance.py:1240} INFO - 
--------------------------------------------------------------------------------
[2022-12-01 14:50:28,463] {taskinstance.py:1259} INFO - Executing <Task(BigQueryCreateExternalTableOperator): bigquery_external_table_task> on 2022-11-30 00:00:00+00:00
[2022-12-01 14:50:28,473] {standard_task_runner.py:52} INFO - Started process 451 to run task
[2022-12-01 14:50:28,487] {standard_task_runner.py:76} INFO - Running: ['***', 'tasks', 'run', 'data_ingestion_gcs_dag', 'bigquery_external_table_task', 'scheduled__2022-11-30T00:00:00+00:00', '--job-id', '4', '--raw', '--subdir', 'DAGS_FOLDER/data_ingestion_gcs_dag.py', '--cfg-path', '/tmp/tmpzhglnkye', '--error-file', '/tmp/tmpa4x705y1']
[2022-12-01 14:50:28,489] {standard_task_runner.py:77} INFO - Job 4: Subtask bigquery_external_table_task
[2022-12-01 14:50:28,598] {logging_mixin.py:109} INFO - Running <TaskInstance: data_ingestion_gcs_dag.bigquery_external_table_task scheduled__2022-11-30T00:00:00+00:00 [running]> on host 09c0add5a9ae
[2022-12-01 14:50:28,783] {taskinstance.py:1426} INFO - Exporting the following env vars:
AIRFLOW_CTX_DAG_OWNER=***
AIRFLOW_CTX_DAG_ID=data_ingestion_gcs_dag
AIRFLOW_CTX_TASK_ID=bigquery_external_table_task
AIRFLOW_CTX_EXECUTION_DATE=2022-11-30T00:00:00+00:00
AIRFLOW_CTX_DAG_RUN_ID=scheduled__2022-11-30T00:00:00+00:00
[2022-12-01 14:50:28,785] {crypto.py:82} WARNING - empty cryptography key - values will not be stored encrypted.
[2022-12-01 14:50:28,789] {taskinstance.py:1700} ERROR - Task failed with exception
Traceback (most recent call last):
  File "/home/airflow/.local/lib/python3.7/site-packages/airflow/models/taskinstance.py", line 1329, in _run_raw_task
    self._execute_task_with_callbacks(context)
  File "/home/airflow/.local/lib/python3.7/site-packages/airflow/models/taskinstance.py", line 1455, in _execute_task_with_callbacks
    result = self._execute_task(context, self.task)
  File "/home/airflow/.local/lib/python3.7/site-packages/airflow/models/taskinstance.py", line 1511, in _execute_task
    result = execute_callable(context=context)
  File "/home/airflow/.local/lib/python3.7/site-packages/airflow/providers/google/cloud/operators/bigquery.py", line 1196, in execute
    table_resource=self.table_resource,
  File "/home/airflow/.local/lib/python3.7/site-packages/airflow/providers/google/common/hooks/base_google.py", line 423, in inner_wrapper
    kwargs['project_id'] = self.project_id
  File "/home/airflow/.local/lib/python3.7/site-packages/airflow/providers/google/common/hooks/base_google.py", line 312, in project_id
    _, project_id = self._get_credentials_and_project_id()
  File "/home/airflow/.local/lib/python3.7/site-packages/airflow/providers/google/common/hooks/base_google.py", line 242, in _get_credentials_and_project_id
    delegates=delegates,
  File "/home/airflow/.local/lib/python3.7/site-packages/airflow/providers/google/cloud/utils/credentials_provider.py", line 335, in get_credentials_and_project_id
    return _CredentialProvider(*args, **kwargs).get_credentials_and_project()
  File "/home/airflow/.local/lib/python3.7/site-packages/airflow/providers/google/cloud/utils/credentials_provider.py", line 237, in get_credentials_and_project
    credentials, project_id = self._get_credentials_using_key_path()
  File "/home/airflow/.local/lib/python3.7/site-packages/airflow/providers/google/cloud/utils/credentials_provider.py", line 287, in _get_credentials_using_key_path
    self.key_path, scopes=self.scopes
  File "/home/airflow/.local/lib/python3.7/site-packages/google/oauth2/service_account.py", line 239, in from_service_account_file
    filename, require=["client_email", "token_uri"]
  File "/home/airflow/.local/lib/python3.7/site-packages/google/auth/_service_account_info.py", line 72, in from_filename
    with io.open(filename, "r", encoding="utf-8") as json_file:
FileNotFoundError: [Errno 2] No such file or directory: '/.google/credentials/google_credentials.json'
[2022-12-01 14:50:28,816] {taskinstance.py:1277} INFO - Marking task as UP_FOR_RETRY. dag_id=data_ingestion_gcs_dag, task_id=bigquery_external_table_task, execution_date=20221130T000000, start_date=20221201T145028, end_date=20221201T145028
[2022-12-01 14:50:28,869] {standard_task_runner.py:92} ERROR - Failed to execute job 4 for task bigquery_external_table_task
Traceback (most recent call last):
  File "/home/airflow/.local/lib/python3.7/site-packages/airflow/task/task_runner/standard_task_runner.py", line 85, in _start_by_fork
    args.func(args, dag=self.dag)
  File "/home/airflow/.local/lib/python3.7/site-packages/airflow/cli/cli_parser.py", line 48, in command
    return func(*args, **kwargs)
  File "/home/airflow/.local/lib/python3.7/site-packages/airflow/utils/cli.py", line 92, in wrapper
    return f(*args, **kwargs)
  File "/home/airflow/.local/lib/python3.7/site-packages/airflow/cli/commands/task_command.py", line 298, in task_run
    _run_task_by_selected_method(args, dag, ti)
  File "/home/airflow/.local/lib/python3.7/site-packages/airflow/cli/commands/task_command.py", line 107, in _run_task_by_selected_method
    _run_raw_task(args, ti)
  File "/home/airflow/.local/lib/python3.7/site-packages/airflow/cli/commands/task_command.py", line 184, in _run_raw_task
    error_file=args.error_file,
  File "/home/airflow/.local/lib/python3.7/site-packages/airflow/utils/session.py", line 70, in wrapper
    return func(*args, session=session, **kwargs)
  File "/home/airflow/.local/lib/python3.7/site-packages/airflow/models/taskinstance.py", line 1329, in _run_raw_task
    self._execute_task_with_callbacks(context)
  File "/home/airflow/.local/lib/python3.7/site-packages/airflow/models/taskinstance.py", line 1455, in _execute_task_with_callbacks
    result = self._execute_task(context, self.task)
  File "/home/airflow/.local/lib/python3.7/site-packages/airflow/models/taskinstance.py", line 1511, in _execute_task
    result = execute_callable(context=context)
  File "/home/airflow/.local/lib/python3.7/site-packages/airflow/providers/google/cloud/operators/bigquery.py", line 1196, in execute
    table_resource=self.table_resource,
  File "/home/airflow/.local/lib/python3.7/site-packages/airflow/providers/google/common/hooks/base_google.py", line 423, in inner_wrapper
    kwargs['project_id'] = self.project_id
  File "/home/airflow/.local/lib/python3.7/site-packages/airflow/providers/google/common/hooks/base_google.py", line 312, in project_id
    _, project_id = self._get_credentials_and_project_id()
  File "/home/airflow/.local/lib/python3.7/site-packages/airflow/providers/google/common/hooks/base_google.py", line 242, in _get_credentials_and_project_id
    delegates=delegates,
  File "/home/airflow/.local/lib/python3.7/site-packages/airflow/providers/google/cloud/utils/credentials_provider.py", line 335, in get_credentials_and_project_id
    return _CredentialProvider(*args, **kwargs).get_credentials_and_project()
  File "/home/airflow/.local/lib/python3.7/site-packages/airflow/providers/google/cloud/utils/credentials_provider.py", line 237, in get_credentials_and_project
    credentials, project_id = self._get_credentials_using_key_path()
  File "/home/airflow/.local/lib/python3.7/site-packages/airflow/providers/google/cloud/utils/credentials_provider.py", line 287, in _get_credentials_using_key_path
    self.key_path, scopes=self.scopes
  File "/home/airflow/.local/lib/python3.7/site-packages/google/oauth2/service_account.py", line 239, in from_service_account_file
    filename, require=["client_email", "token_uri"]
  File "/home/airflow/.local/lib/python3.7/site-packages/google/auth/_service_account_info.py", line 72, in from_filename
    with io.open(filename, "r", encoding="utf-8") as json_file:
FileNotFoundError: [Errno 2] No such file or directory: '/.google/credentials/google_credentials.json'
[2022-12-01 14:50:28,899] {local_task_job.py:154} INFO - Task exited with return code 1
[2022-12-01 14:50:28,947] {local_task_job.py:264} INFO - 0 downstream tasks scheduled from follow-on schedule check
